<mujoco model="humanoid_legged_description">
    <compiler angle="radian" meshdir="../meshes/" />
    <size njmax="500" nconmax="100" />
    <asset>
        <texture type="skybox" builtin="gradient" rgb1="0.4 0.6 0.8" width="128" height="128"/>
        <texture name="grid" type="2d" builtin="checker" rgb1=".1 .2 .3" rgb2=".2 .3 .4" width="300" height="300"/>
        <material name="grid" texture="grid" texrepeat="8 8" reflectance=".1"/>
        <mesh name="base_link" file="base_link.STL" />
        <mesh name="leg_l1_link" file="leg_l1_link.STL" />
        <mesh name="leg_l2_link" file="leg_l2_link.STL" />
        <mesh name="leg_l3_link" file="leg_l3_link.STL" />
        <mesh name="leg_l4_link" file="leg_l4_link.STL" />
        <mesh name="leg_l5_link" file="leg_l5_link.STL" />
        <mesh name="leg_l6_link" file="leg_l6_link.STL" />
        <mesh name="leg_r1_link" file="leg_r1_link.STL" />
        <mesh name="leg_r2_link" file="leg_r2_link.STL" />
        <mesh name="leg_r3_link" file="leg_r3_link.STL" />
        <mesh name="leg_r4_link" file="leg_r4_link.STL" />
        <mesh name="leg_r5_link" file="leg_r5_link.STL" />
        <mesh name="leg_r6_link" file="leg_r6_link.STL" />
    </asset>
    <worldbody>
    <light directional="false" cutoff="60" exponent="1" diffuse=".5 .5 .5" specular=".1 .1 .1" pos="0.5 0.1 0.8" dir="-0.5 -0.1 -0.8"/>
        <geom size="10 10 .01" type="plane" material="grid"/>
        <body name="base_link" pos="0 0 2">
            <freejoint/>
            <inertial pos="0.02394 0.00047 0.287306" quat="0.999787 0.00893974 -0.0179368 -0.0048468" mass="31.1109" diaginertia="2.38989 1.6598 1.15201" />
            <geom type="mesh" contype="0" conaffinity="0" group="1" rgba="0.75294 0.75294 0.75294 1" mesh="base_link" />
            <geom type="mesh" rgba="0.75294 0.75294 0.75294 1" mesh="base_link" />
            <site name="imu" pos="0 0 0"/>
            <body name="leg_l1_link" pos="0.0167452 0.158 -0.0250736" quat="0 -0.382683 0 0.92388">
                <inertial pos="0.072108 0 -0.006156" quat="0 0.721778 0 0.692124" mass="1.70312" diaginertia="0.00426736 0.002706 0.00235764" />
                <joint name="leg_l1_joint" pos="0 0 0" axis="-1 0 0"  damping='0.2'/>
                <geom type="mesh" contype="0" conaffinity="0" group="1" rgba="0.898039 0.917647 0.929412 1" mesh="leg_l1_link" />
                <geom type="mesh" rgba="0.898039 0.917647 0.929412 1" mesh="leg_l1_link" />
                <body name="leg_l2_link" pos="0.08 0 -0.042" quat="0.0132281 0.706983 0.0132281 -0.706983">
                    <inertial pos="0.0396479 -1.27833e-06 -0.0357769" quat="0.946283 0 -0.32334 0" mass="1.09949" diaginertia="0.00411386 0.002946 0.00262414" />
                    <joint name="leg_l2_joint" pos="0 0 0" axis="-1 0 0"   damping='0.2'/>
                    <geom type="mesh" contype="0" conaffinity="0" group="1" rgba="0.898039 0.917647 0.929412 1" mesh="leg_l2_link" />
                    <geom type="mesh" rgba="0.898039 0.917647 0.929412 1" mesh="leg_l2_link" />
                    <body name="leg_l3_link" pos="0.092 0 -0.08" quat="0.92388 0 -0.382683 0">
                        <inertial pos="-0.0159398 0.00024584 -0.214302" quat="0.694261 -0.142764 -0.146297 0.690084" mass="11.2874" diaginertia="0.183109 0.158438 0.0563741" />
                        <joint name="leg_l3_joint" pos="0 0 0" axis="0 -1 0"   damping='0.2'/>
                        <geom type="mesh" contype="0" conaffinity="0" group="1" rgba="0.898039 0.898039 0.898039 1" mesh="leg_l3_link" />
                        <!-- <geom type="mesh" rgba="0.898039 0.898039 0.898039 1" mesh="leg_l3_link" /> -->
                        <body name="leg_l4_link" pos="0 0 -0.459105">
                            <inertial pos="0.011266 0.000171 -0.112137" quat="0.999955 -0.00355323 -0.00866498 0.00169984" mass="3.23555" diaginertia="0.014793 0.0130564 0.00498565" />
                            <joint name="leg_l4_joint" pos="0 0 0" axis="0 -1 0"   damping='0.2'/>
                            <geom type="mesh" contype="0" conaffinity="0" group="1" rgba="0.898039 0.917647 0.929412 1" mesh="leg_l4_link" />
                            <!-- <geom type="mesh" rgba="0.898039 0.917647 0.929412 1" mesh="leg_l4_link" /> -->
                            <body name="leg_l5_link" pos="2.21009e-05 0 -0.321307">
                                <inertial pos="-3.21773e-09 -3.21773e-09 0" quat="0.5 0.5 -0.5 0.5" mass="0.179272" diaginertia="4.1e-05 2.5e-05 2.5e-05" />
                                <joint name="leg_l5_joint" pos="0 0 0" axis="0 1 0"   damping='0.2'/>
                                <geom type="mesh" contype="0" conaffinity="0" group="1" rgba="0.898039 0.898039 0.898039 1" mesh="leg_l5_link" />
                                <geom type="mesh" rgba="0.898039 0.898039 0.898039 1" mesh="leg_l5_link" />
                                <body name="leg_l6_link" pos="0 0 0">
                                    <inertial pos="0.0428722 0 -0.0287265" quat="0 0.71824 0 0.695796" mass="0.359579" diaginertia="0.00101183 0.000903 0.000192174" />
                                    <joint name="leg_l6_joint" pos="0 0 0" axis="1 0 6.87843e-05"   damping='0.2'/>
                                    <geom size="0.15 0.025 0.008" pos="0.05 -0.0 -0.027" type="box" contype="0" conaffinity="0" group="1" rgba="0.898039 0.917647 0.929412 1"/>
                                    <geom size="0.15 0.025 0.008" pos="0.05 -0.0 -0.027" type="box" rgba="0.8 0 0 0"/>
                                </body>
                            </body>
                        </body>
                    </body>
                </body>
            </body>
            <body name="leg_r1_link" pos="0.0167452 -0.158 -0.0250736" quat="0 -0.382683 0 0.92388">
                <inertial pos="0.0634478 8.35629e-08 -0.00523903" quat="0 0.721778 0 0.692124" mass="0.812038" diaginertia="0.00426736 0.002706 0.00235764" />
                <joint name="leg_r1_joint" pos="0 0 0" axis="-1 0 0"   damping='0.2'/>
                <geom type="mesh" contype="0" conaffinity="0" group="1" rgba="0.898039 0.917647 0.929412 1" mesh="leg_r1_link" />
                <geom type="mesh" rgba="0.898039 0.917647 0.929412 1" mesh="leg_r1_link" />
                <body name="leg_r2_link" pos="0.08 0 -0.042" quat="0 0.707107 0 -0.707107">
                    <inertial pos="0.0396479 -1.27833e-06 -0.0357769" quat="0.946283 0 -0.32334 0" mass="1.09949" diaginertia="0.00411386 0.002946 0.00262414" />
                    <joint name="leg_r2_joint" pos="0 0 0" axis="-1 0 0"   damping='0.2'/>
                    <geom type="mesh" contype="0" conaffinity="0" group="1" rgba="0.898039 0.917647 0.929412 1" mesh="leg_r2_link" />
                    <geom type="mesh" rgba="0.898039 0.917647 0.929412 1" mesh="leg_r2_link" />
                    <body name="leg_r3_link" pos="0.092 0 -0.08" quat="0.92388 0 -0.382683 0">
                        <inertial pos="-0.0158963 0.000244401 -0.214095" quat="0.694261 -0.142764 -0.146297 0.690084" mass="11.2704" diaginertia="0.183109 0.158438 0.0563741" />
                        <joint name="leg_r3_joint" pos="0 0 0" axis="0 -1 0"   damping='0.2'/>
                        <geom type="mesh" contype="0" conaffinity="0" group="1" rgba="0.898039 0.917647 0.929412 1" mesh="leg_r3_link" />
                        <geom type="mesh" rgba="0.898039 0.917647 0.929412 1" mesh="leg_r3_link" />
                        <body name="leg_r4_link" pos="0 0 -0.459105">
                            <inertial pos="0.0115517 -0.000630805 -0.123219" quat="0.999955 -0.00355323 -0.00866498 0.00169984" mass="1.68736" diaginertia="0.014793 0.0130564 0.00498565" />
                            <joint name="leg_r4_joint" pos="0 0 0" axis="0 -1 0"   damping='0.2'/>
                            <geom type="mesh" contype="0" conaffinity="0" group="1" rgba="0.898039 0.917647 0.929412 1" mesh="leg_r4_link" />
                            <geom type="mesh" rgba="0.898039 0.917647 0.929412 1" mesh="leg_r4_link" />
                            <body name="leg_r5_link" pos="2.21009e-05 0 -0.321307">
                                <inertial pos="-3.21773e-09 -3.21773e-09 0" quat="0.5 0.5 -0.5 0.5" mass="0.179272" diaginertia="4.1e-05 2.5e-05 2.5e-05" />
                                <joint name="leg_r5_joint" pos="0 0 0" axis="0 1 0"   damping='0.2'/>
                                <geom type="mesh" contype="0" conaffinity="0" group="1" rgba="0.898039 0.898039 0.898039 1" mesh="leg_r5_link" />
                                <geom type="mesh" rgba="0.898039 0.898039 0.898039 1" mesh="leg_r5_link" />
                                <body name="leg_r6_link" pos="0 0 0">
                                    <inertial pos="0.0428722 0 -0.0287265" quat="0 0.71824 0 0.695796" mass="0.359579" diaginertia="0.00101183 0.000903 0.000192174" />
                                    <joint name="leg_r6_joint" pos="0 0 0" axis="1 0 6.87843e-05"   damping='0.2'/>
                                    <geom size="0.15 0.025 0.008" pos="0.05 -0.0 -0.027" type="box" contype="0" conaffinity="0" group="1" rgba="0.898039 0.917647 0.929412 1"/>
                                    <geom size="0.15 0.025 0.008" pos="0.05 -0.0 -0.027" type="box" rgba="0.8 0 0 0"/>
                                </body>
                            </body>
                        </body>
                    </body>
                </body>
            </body>
        </body>
    </worldbody>
    <actuator>
        <motor gear="1" joint="leg_l1_joint" name="leg_l1_motor" ctrllimited="true"  ctrlrange='-150 150'/>
        <motor gear="1" joint="leg_l2_joint" name="leg_l2_motor" ctrllimited="true"  ctrlrange='-150 150'/>
        <motor gear="1" joint="leg_l3_joint" name="leg_l3_motor" ctrllimited="true"  ctrlrange='-200 200'/>
        <motor gear="1" joint="leg_l4_joint" name="leg_l4_motor" ctrllimited="true"  ctrlrange='-200 200'/>
        <motor gear="1" joint="leg_l5_joint" name="leg_l5_motor" ctrllimited="true"  ctrlrange='-90 90'/>
        <motor gear="1" joint="leg_l6_joint" name="leg_l6_motor" ctrllimited="true"  ctrlrange='-90 90'/>
        <motor gear="1" joint="leg_r1_joint" name="leg_r1_motor" ctrllimited="true"  ctrlrange='-150 150'/>
        <motor gear="1" joint="leg_r2_joint" name="leg_r2_motor" ctrllimited="true"  ctrlrange='-150 150'/>
        <motor gear="1" joint="leg_r3_joint" name="leg_r3_motor" ctrllimited="true"  ctrlrange='-200 200'/>
        <motor gear="1" joint="leg_r4_joint" name="leg_r4_motor" ctrllimited="true"  ctrlrange='-200 200'/>
        <motor gear="1" joint="leg_r5_joint" name="leg_r5_motor" ctrllimited="true"  ctrlrange='-90 90'/>
        <motor gear="1" joint="leg_r6_joint" name="leg_r6_motor" ctrllimited="true"  ctrlrange='-90 90'/>
    </actuator>
    <sensor>
        <jointpos name="leg_l1_pos" joint="leg_l1_joint"/>
        <jointpos name="leg_l2_pos" joint="leg_l2_joint"/>
        <jointpos name="leg_l3_pos" joint="leg_l3_joint"/>
        <jointpos name="leg_l4_pos" joint="leg_l4_joint"/>
        <jointpos name="leg_l5_pos" joint="leg_l5_joint"/>
        <jointpos name="leg_l6_pos" joint="leg_l6_joint"/>
        <jointpos name="leg_r1_pos" joint="leg_r1_joint"/>
        <jointpos name="leg_r2_pos" joint="leg_r2_joint"/>
        <jointpos name="leg_r3_pos" joint="leg_r3_joint"/>
        <jointpos name="leg_r4_pos" joint="leg_r4_joint"/>
        <jointpos name="leg_r5_pos" joint="leg_r5_joint"/>
        <jointpos name="leg_r6_pos" joint="leg_r6_joint"/>
        <jointvel name="leg_l1_vel" joint="leg_l1_joint"/>
        <jointvel name="leg_l2_vel" joint="leg_l2_joint"/>
        <jointvel name="leg_l3_vel" joint="leg_l3_joint"/>
        <jointvel name="leg_l4_vel" joint="leg_l4_joint"/>
        <jointvel name="leg_l5_vel" joint="leg_l5_joint"/>
        <jointvel name="leg_l6_vel" joint="leg_l6_joint"/>
        <jointvel name="leg_r1_vel" joint="leg_r1_joint"/>
        <jointvel name="leg_r2_vel" joint="leg_r2_joint"/>
        <jointvel name="leg_r3_vel" joint="leg_r3_joint"/>
        <jointvel name="leg_r4_vel" joint="leg_r4_joint"/>
        <jointvel name="leg_r5_vel" joint="leg_r5_joint"/>
        <jointvel name="leg_r6_vel" joint="leg_r6_joint"/>
        <accelerometer name="BodyAcc" site="imu"/>
        <velocimeter name="BodyVel" site="imu"/>
        <gyro name="BodyGyro" site="imu"/>
        <framepos name="BodyPos" objtype="site" objname="imu"/>
        <framequat name="BodyQuat" objtype="site" objname="imu"/>
    </sensor>
</mujoco>
